Workbook

Sheet README
A1: Golden Data Set: Agentic Rule Generation for Cloud Security (Case 14, CloudGuard Labs)
A3: Purpose
A4: Ground-truth data used to design and evaluate the AI rule-generation pipeline: (1) offline evaluation before launch, (2) regression test whenever the model or prompts change, (3) go/no-go gate for the MVP.
A6: Where the data comes from (all real, nothing synthetic)
A7: - CIS Amazon Web Services Foundations Benchmark v7.0.0 and v6.0.0: recommendation IDs, titles, section, profile level, assessment status, as mapped in Prowler's compliance files.
A8: - Prowler open-source CSPM (Apache-2.0): check metadata (severity, risk, remediation, Terraform/CLI fixes) and the check source code. The PASS/FAIL messages were extracted directly from each check's Python code.
A9: - AWS What's New RSS feed: the 100 most recent real announcements (14-26 Oct 2026) for the triage set.
A11: Sheets
A12: Positive_Set: one row per (CIS recommendation x reference check) pair. 'What a correct rule looks like' = expected rule output.
A13: Edge_Cases: cases found in the real data that a naive generator gets wrong (one-to-many mappings, shared checks, manual-only controls, no-automation controls, account-vs-resource scope).
A14: Triage_Set: real AWS announcements with an expected triage label: does this need a new rule, an update to an existing rule, or no rule?
A15: Version_Drift: real changes between CIS v6.0 and v7.0. Tests the maintenance agent: which existing rules must be added, retired, re-numbered or re-mapped.
... A27: Key derived facts for the deck
A28: CIS v7.0 recommendations | B28: 70 | C28: in Prowler's CIS v7.0 AWS mapping (counted in build script)
A29: Positive_Set rows | B29: =COUNTA(Positive_Set!A2:A87) -> 86 | C29: recommendation x reference-check pairs
A30: Distinct reference checks | B30: 82 | C30: distinct Prowler checks mapped to CIS v7.0 (counted in build script)
A31: Edge cases | B31: =COUNTA(Edge_Cases!A2:A52) -> 51
A32: Triage announcements | B32: =COUNTA(Triage_Set!A2:A101) -> 100 | C32: real AWS announcements, 14-26 Oct 2026
A33: ...of which need a rule (draft label) | B33: =COUNTIF(Triage_Set!F2:F101,"Y") -> 11 | C33: the rest are noise the Watcher agent must filter out
A34: Version drift items (CIS 6.0 -> 7.0) | B34: =COUNTA(Version_Drift!A2:A32) -> 31
A35: Critical/High severity rows | B35: =COUNTIF(Positive_Set!L2:L87,"critical")+COUNTIF(Positive_Set!L2:L87,"high") -> 37
A36: Rows in tier T3 (mandatory 2-SME sign-off) | B36: =COUNTIF(Positive_Set!T2:T87,"T3") -> 26

Sheet Positive_Set
A1: GS_ID | B1: CIS_ID | C1: CIS_Recommendation | D1: CIS_Section | E1: CIS_Profile | F1: CIS_Assessment | G1: Expected_Check_ID | H1: Check_Title | I1: Service | J1: Resource_Type | K1: Resource_Group | L1: Expected_Severity | M1: Risk (Prowler) | N1: Expected_FAIL_message | O1: Expected_PASS_message | P1: Compliant_Fixture (Terraform) | Q1: Remediation_CLI | R1: AWS_Docs_URLs | S1: Reference_Rule_Code_URL | T1: Proposed_Risk_Tier
A2: P-001 | B2: 2.1.1 | C2: Ensure centralized root access in AWS Organizations | D2: 2 Identity and Access Management | E2: Level 2 | F2: Manual | G2: iam_root_credentials_management_enabled | H2: AWS Organization has centralized root credentials management enabled | I2: iam | J2: Other | K2: IAM | L2: high | M2: Without central control, member accounts can retain or recover long-term root credentials, weakening confidentiality and integrity. Threats include: - Account takeover via root email recovery - Persistent access through root keys - Unfixable lockouts from misconfigured policies - Bypass of separation of duties | N2: Root credentials management is not enabled. | O2: Root credentials management is enabled. | Q2: aws iam enable-organizations-root-credentials-management | R2: https://docs.aws.amazon.com/IAM/latest/UserGuide/id_root-user.html#id_root-user-access-management https://docs.aws.amazon.com/IAM/latest/UserGuide/id_root-enable-root-access.html | S2: https://github.com/prowler-cloud/prowler/blob/master/prowler/providers/aws/services/iam/iam_root_credentials_management_enabled/iam_root_credentials_management_enabled.py | T2: =IF(OR(L2="critical",AND(L2="high",OR(K2="IAM",K2="network"))),"T3",IF(OR(L2="high",L2="medium"),"T2","T1")) -> T3
A3: P-002 | B3: 2.1.5 | C3: Ensure delegated admin manages AWS Organizations policies | D3: 2 Identity and Access Management | E3: Level 2 | F3: Manual | G3: organizations_delegated_administrators | H3: AWS Organization has only trusted delegated administrators | I3: organizations | J3: Other | K3: governance | L3: critical | M3: Unapproved delegated administrators can alter SCPs, invite/move accounts, and create privileged roles, enabling privilege escalation. This undermines guardrails, risking loss of integrity, exposure of confidentiality across accounts, and impacts availability through organization-wide policy changes. | N3: AWS Organization {organizations_client.organization.id} has an untrusted Delegated Administrator: {delegated_administrator.id}. | O3: AWS Organization {organizations_client.organization.id} has a trusted Delegated Administrator: {delegated_administrator.id}. | R3: https://docs.aws.amazon.com/organizations/latest/userguide/orgs_delegate_policies.html | S3: https://github.com/prowler-cloud/prowler/blob/master/prowler/providers/aws/services/organizations/organizations_delegated_administrators/organizations_delegated_administrators.py | T3: =IF(OR(L3="critical",AND(L3="high",OR(K3="IAM",K3="network"))),"T3",IF(OR(L3="high",L3="medium"),"T2","T1")) -> T3
A4: P-003 | B4: 2.1.6 | C4: Ensure delegated admins manage AWS Organizations-integrated services | D4: 2 Identity and Access Management | E4: Level 2 | F4: Manual | G4: organizations_delegated_administrators | H4: AWS Organization has only trusted delegated administrators | I4: organizations | J4: Other | K4: governance | L4: critical | M4: Unapproved delegated administrators can alter SCPs, invite/move accounts, and create privileged roles, enabling privilege escalation. This undermines guardrails, risking loss of integrity, exposure of confidentiality across accounts, and impacts availability through organization-wide policy changes. | N4: AWS Organization {organizations_client.organization.id} has an untrusted Delegated Administrator: {delegated_administrator.id}. | O4: AWS Organization {organizations_client.organization.id} has a trusted Delegated Administrator: {delegated_administrator.id}. | R4: https://docs.aws.amazon.com/organizations/latest/userguide/orgs_delegate_policies.html | S4: https://github.com/prowler-cloud/prowler/blob/master/prowler/providers/aws/services/organizations/organizations_delegated_administrators/organizations_delegated_administrators.py | T4: =IF(OR(L4="critical",AND(L4="high",OR(K4="IAM",K4="network"))),"T3",IF(OR(L4="high",L4="medium"),"T2","T1")) -> T3
A5: P-004 | B5: 2.2 | C5: Maintain current AWS account contact details | D5: 2 Identity and Access Management | E5: Level 1 | F5: Manual | G5: account_maintain_current_contact_details | H5: AWS account contact information is current | I5: account | J5: Other | K5: governance | L5: medium | M5: Outdated or single-person contacts delay security notifications, slow incident response, and complicate account recovery. AWS may throttle services during abuse mitigation, reducing availability. Missed alerts enable ongoing misuse, risking data exfiltration and unauthorized changes (integrity). | P5: # Set the Security alternate contact for the AWS account resource "aws_account_alternate_contact" "<example_resource_name>" { alternate_contact_type = "SECURITY" # Critical: ensures AWS can reach your security team email_address = "<SECURITY_EMAIL>" # Critical: contact destination name = "<SECURITY_CONTACT_NAME>" phone_number = "<SECURITY_PHONE>" title = "Security" } | Q5: aws account put-alternate-contact --alternate-contact-type=SECURITY --email-address=<SECURITY_EMAIL> --name="<SECURITY_CONTACT_NAME>" --phone-number="<SECURITY_PHONE>" --title="Security" | R5: https://docs.aws.amazon.com/security-ir/latest/userguide/update-account-contact-info.html https://docs.aws.amazon.com/accounts/latest/reference/manage-acct-update-contact-primary.html https://aws.amazon.com/blogs/security/update-the-alternate-security-contact-across-your-aws-accounts-for-timely-security-notifications/ https://docs.aws.amazon.com/organizations/latest/userguide/orgs_manage_accounts_update_contacts.html https://docs.aws.amazon.com/accounts/latest/reference/manage-acct-update-contact-alternate.html | S5: https://github.com/prowler-cloud/prowler/blob/master/prowler/providers/aws/services/account/account_maintain_current_contact_details/account_maintain_current_contact_details.py | T5: =IF(OR(L5="critical",AND(L5="high",OR(K5="IAM",K5="network"))),"T3",IF(OR(L5="high",L5="medium"),"T2","T1")) -> T2
A6: P-005 | B6: 2.3 | C6: Ensure security contact information is registered | D6: 2 Identity and Access Management | E6: Level 1 | F6: Manual | G6: account_security_contact_information_is_registered | H6: AWS account has security alternate contact registered | I6: account | J6: Other | K6: governance | L6: medium | M6: Missing or outdated security contact can delay or prevent AWS advisories from reaching responders, increasing risk to: - Confidentiality: data exfiltration from undetected compromise - Integrity: unauthorized changes persist longer - Availability: resource abuse (e.g., cryptomining) and outages | P6: # Set the SECURITY alternate contact for the current AWS account resource "aws_account_alternate_contact" "<example_resource_name>" { alternate_contact_type = "SECURITY" # Critical: sets Security contact type email_address = "security@example.com" # Contact email name = "Security Team" # Contact name phone_number = "+1-555-0100" # Contact phone } | Q6: aws account put-alternate-contact --alternate-contact-type SECURITY --email-address <EMAIL_ADDRESS> --name <CONTACT_NAME> --phone-number <PHONE_NUMBER> | S6: https://github.com/prowler-cloud/prowler/blob/master/prowler/providers/aws/services/account/account_security_contact_information_is_registered/account_security_contact_information_is_registered.py | T6: =IF(OR(L6="critical",AND(L6="high",OR(K6="IAM",K6="network"))),"T3",IF(OR(L6="high",L6="medium"),"T2","T1")) -> T2
A7: P-006 | B7: 2.4 | C7: Ensure no 'root' user account access key exists | D7: 2 Identity and Access Management | E7: Level 1 | F7: Automated | G7: iam_no_root_access_key | H7: Root account has no active access keys | I7: iam | J7: AwsIamAccessKey | K7: IAM | L7: critical | M7: Root access keys provide unrestricted API access. If exposed or misused, attackers can: - Turn off logging and alter policies (integrity) - Read or export data (confidentiality) - Delete resources and lock out admins (availability) Long-lived keys can persist and may bypass console-only MFA. | N7: Root account has two active access keys | O7: Root account has password configured but no access keys. | R7: https://docs.aws.amazon.com/IAM/latest/UserGuide/id_credentials_access-keys.html https://docs.aws.amazon.com/IAM/latest/UserGuide/id_credentials_getting-report.html | S7: https://github.com/prowler-cloud/prowler/blob/master/prowler/providers/aws/services/iam/iam_no_root_access_key/iam_no_root_access_key.py | T7: =IF(OR(L7="critical",AND(L7="high",OR(K7="IAM",K7="network"))),"T3",IF(OR(L7="high",L7="medium"),"T2","T1")) -> T3
A8: P-007 | B8: 2.5 | C8: Ensure MFA is enabled for the 'root' user account | D8: 2 Identity and Access Management | E8: Level 1 | F8: Automated | G8: iam_root_mfa_enabled | H8: Root account has MFA enabled | I8: iam | J8: AwsIamUser | K8: IAM | L8: critical | M8: Without MFA, compromise of the root password or access keys can lead to full account takeover. An attacker with root can disable protections, steal or delete data, change billing, and create persistent admins, undermining confidentiality, integrity, and availability. | N8: Root account has credentials without MFA | O8: Root account has credentials with MFA enabled. | R8: https://docs.aws.amazon.com/IAM/latest/UserGuide/id_root-user.html#id_root-user_manage_mfa | S8: https://github.com/prowler-cloud/prowler/blob/master/prowler/providers/aws/services/iam/iam_root_mfa_enabled/iam_root_mfa_enabled.py | T8: =IF(OR(L8="critical",AND(L8="high",OR(K8="IAM",K8="network"))),"T3",IF(OR(L8="high",L8="medium"),"T2","T1")) -> T3
A9: P-008 | B9: 2.6 | C9: Ensure hardware MFA is enabled for the 'root' user account | D9: 2 Identity and Access Management | E9: Level 2 | F9: Manual | G9: iam_root_hardware_mfa_enabled | H9: Root account has a hardware MFA device enabled | I9: iam | J9: AwsIamUser | K9: IAM | L9: critical | M9: Without hardware MFA on the root user: - No MFA: stolen password/keys enable full account takeover. - Virtual MFA: device compromise or backup restoration weakens second-factor assurance. An attacker could delete resources, change policies, and disable logging, harming confidentiality, integrity, and availability. | N9: Root account has credentials with virtual MFA | O9: Root account has credentials with hardware MFA enabled. | R9: https://docs.aws.amazon.com/IAM/latest/UserGuide/id_root-user.html#id_root-user_manage_mfa | S9: https://github.com/prowler-cloud/prowler/blob/master/prowler/providers/aws/services/iam/iam_root_hardware_mfa_enabled/iam_root_hardware_mfa_enabled.py | T9: =IF(OR(L9="critical",AND(L9="high",OR(K9="IAM",K9="network"))),"T3",IF(OR(L9="high",L9="medium"),"T2","T1")) -> T3
A10: P-009 | B10: 2.7 | C10: Eliminate use of the 'root' user for administrative and daily tasks | D10: 2 Identity and Access Management | E10: Level 1 | F10: Manual | G10: iam_avoid_root_usage | H10: AWS account root user has not been used in the last day | I10: iam | J10: AwsIamUser | K10: IAM | L10: high | M10: Recent root usage expands blast radius: - Data exfiltration (confidentiality) - Policy/key tampering (integrity) - Resource deletion and billing changes (availability) Routine use reduces anomaly visibility and eases account takeover impact. | N10: Root user in the account was last accessed {days_since_accessed} days ago. | O10: Root user in the account wasn't accessed in the last {maximum_access_days} days. | R10: https://docs.aws.amazon.com/IAM/latest/UserGuide/root-user-best-practices.html | S10: https://github.com/prowler-cloud/prowler/blob/master/prowler/providers/aws/services/iam/iam_avoid_root_usage/iam_avoid_root_usage.py | T10: =IF(OR(L10="critical",AND(L10="high",OR(K10="IAM",K10="network"))),"T3",IF(OR(L10="high",L10="medium"),"T2","T1")) -> T3
A11: P-010 | B11: 2.8 | C11: Ensure IAM password policy requires minimum length of 14 or greater | D11: 2 Identity and Access Management | E11: Level 1 | F11: Automated | G11: iam_password_policy_minimum_length_14 | H11: IAM password policy requires passwords to be at least 14 characters long | I11: iam | J11: AwsIamPolicy | K11: IAM | L11: medium | M11: Low minimum length reduces entropy, easing brute force and credential stuffing. Compromised IAM users enable console access, unauthorized changes, and lateral movement, leading to data exposure (confidentiality) and tampering (integrity). | N11: IAM password policy does not require minimum length of 14 characters. | O11: IAM password policy requires minimum length of 14 characters. | P11: resource "aws_iam_account_password_policy" "<example_resource_name>" { minimum_password_length = 14 # Critical: enforces minimum password length >=14 } | Q11: aws iam update-account-password-policy --minimum-password-length 14 | R11: https://docs.aws.amazon.com/config/latest/developerguide/iam-password-policy.html https://docs.aws.amazon.com/IAM/latest/UserGuide/id_credentials_passwords_account-policy.html https://docs.aws.amazon.com/sdk-for-ruby/v3/api/Aws/IAM/Resource.html | S11: https://github.com/prowler-cloud/prowler/blob/master/prowler/providers/aws/services/iam/iam_password_policy_minimum_length_14/iam_password_policy_minimum_length_14.py | T11: =IF(OR(L11="critical",AND(L11="high",OR(K11="IAM",K11="network"))),"T3",IF(OR(L11="high",L11="medium"),"T2","T1")) -> T2
A12: P-011 | B12: 2.9 | C12: Ensure IAM password policy prevents password reuse | D12: 2 Identity and Access Management | E12: Level 1 | F12: Automated | G12: iam_password_policy_reuse_24 | H12: IAM password policy prevents reuse of the last 24 passwords | I12: iam | J12: AwsIamPolicy | K12: IAM | L12: medium | M12: If fewer than 24 passwords are remembered, users can cycle back to recent secrets, undermining rotation. Attackers with previously exposed passwords can regain console access after a change, reducing confidentiality and integrity and increasing success of credential-stuffing with known credentials. | N12: IAM password policy reuse prevention is less than 24 or not set. | O12: IAM password policy reuse prevention is equal to 24. | P12: resource "aws_iam_account_password_policy" "<example_resource_name>" { password_reuse_prevention = 24 # Critical: require last 24 passwords cannot be reused } | Q12: aws iam update-account-password-policy --password-reuse-prevention 24 | R12: https://docs.aws.amazon.com/IAM/latest/UserGuide/id_credentials_passwords_account-policy.html | S12: https://github.com/prowler-cloud/prowler/blob/master/prowler/providers/aws/services/iam/iam_password_policy_reuse_24/iam_password_policy_reuse_24.py | T12: =IF(OR(L12="critical",AND(L12="high",OR(K12="IAM",K12="network"))),"T3",IF(OR(L12="high",L12="medium"),"T2","T1")) -> T2
A13: P-012 | B13: 2.10 | C13: Ensure multi-factor authentication (MFA) is enabled for all IAM users that have a console password | D13: 2 Identity and Access Management | E13: Level 1 | F13: Automated | G13: iam_user_mfa_enabled_console_access | H13: IAM user has MFA enabled for console access or no console password is set | I13: iam | J13: AwsIamUser | K13: IAM | L13: high | M13: Without MFA, a stolen or brute-forced password grants full interactive access. Attackers can: - Change policies or keys - Exfiltrate data - Create backdoor users - Disable logging. This enables account takeover, threatens confidentiality and integrity, and can disrupt availability. | N13: User {user['user']} has Console Password enabled but MFA disabled. | O13: User {user['user']} has Console Password enabled and MFA enabled. | P13: # IAM user without console password resource "aws_iam_user" "user" { name = "<example_resource_name>" # Critical: Do NOT create an aws_iam_user_login_profile resource. # Without a login profile, no console password is set, so the check passes. } | Q13: aws iam delete-login-profile --user-name <IAM_USER_NAME> | R13: https://docs.aws.amazon.com/IAM/latest/UserGuide/id_credentials_mfa_enable_virtual.html | S13: https://github.com/prowler-cloud/prowler/blob/master/prowler/providers/aws/services/iam/iam_user_mfa_enabled_console_access/iam_user_mfa_enabled_console_access.py | T13: =IF(OR(L13="critical",AND(L13="high",OR(K13="IAM",K13="network"))),"T3",IF(OR(L13="high",L13="medium"),"T2","T1")) -> T3
A14: P-013 | B14: 2.11 | C14: Ensure credentials unused for 45 days or more are disabled | D14: 2 Identity and Access Management | E14: Level 1 | F14: Automated | G14: iam_user_accesskey_unused | H14: IAM user does not have unused access keys older than 45 days | I14: iam | J14: AwsIamUser | K14: IAM | L14: medium | M14: Active yet unused keys expand the attack surface. If leaked, adversaries gain API access for data exfiltration, unauthorized changes, and resource abuse, harming confidentiality, integrity, and availability. Stale credentials also enable persistence and unexpected cost spikes. | N14: User {user['user']} has not used access key 1 in the last {maximum_expiration_days} days ({access_key_1_last_used_date.days} days). | O14: User {user['user']} does not have access keys. | Q14: aws iam update-access-key --user-name <USER_NAME> --access-key-id <ACCESS_KEY_ID> --status Inactive | R14: https://docs.aws.amazon.com/IAM/latest/UserGuide/id_credentials_finding-unused.html https://docs.aws.amazon.com/securityhub/latest/userguide/iam-controls.html | S14: https://github.com/prowler-cloud/prowler/blob/master/prowler/providers/aws/services/iam/iam_user_accesskey_unused/iam_user_accesskey_unused.py | T14: =IF(OR(L14="critical",AND(L14="high",OR(K14="IAM",K14="network"))),"T3",IF(OR(L14="high",L14="medium"),"T2","T1")) -> T2
A15: P-014 | B15: 2.11 | C15: Ensure credentials unused for 45 days or more are disabled | D15: 2 Identity and Access Management | E15: Level 1 | F15: Automated | G15: iam_user_console_access_unused | H15: IAM user console access is disabled, used within the configured inactivity period, or never used | I15: iam | J15: AwsIamUser | K15: IAM | L15: medium | M15: Dormant console credentials stay valid and invite password spraying, credential stuffing, and breach reuse. Compromise yields interactive access for data discovery/exfiltration and unauthorized IAM or resource changes, degrading confidentiality and integrity, and risking availability. | N15: User {user.name} has not logged in to the console in the past {maximum_expiration_days} days ({time_since_insertion.days} days). | O15: User {user.name} has logged in to the console in the past {maximum_expiration_days} days ({time_since_insertion.days} days). | P15: # IAM user with console access disabled by not creating a login profile resource "aws_iam_user" "<example_resource_name>" { name = "<example_resource_name>" # Critical: Do not define aws_iam_user_login_profile for this user -> no console access } | Q15: aws iam delete-login-profile --user-name <USER_NAME> | R15: https://docs.aws.amazon.com/IAM/latest/UserGuide/id_credentials_finding-unused.html https://docs.aws.amazon.com/securityhub/latest/userguide/iam-controls.html | S15: https://github.com/prowler-cloud/prowler/blob/master/prowler/providers/aws/services/iam/iam_user_console_access_unused/iam_user_console_access_unused.py | T15: =IF(OR(L15="critical",AND(L15="high",OR(K15="IAM",K15="network"))),"T3",IF(OR(L15="high",L15="medium"),"T2","T1")) -> T2
A16: P-015 | B16: 2.12 | C16: Ensure access keys are rotated every 90 days or less | D16: 2 Identity and Access Management | E16: Level 1 | F16: Automated | G16: iam_rotate_access_key_90_days | H16: IAM user does not have active access keys older than 90 days | I16: iam | J16: AwsIamUser | K16: IAM | L16: medium | M16: Long-lived access keys widen the attack window. If a key is leaked in code, logs, or tooling, lack of rotation keeps it valid for abuse, enabling unauthorized API calls, data exfiltration, and tampering. This degrades confidentiality and integrity and can impact availability and cost through destructive or excessive operations. | N16: User {user['user']} has not rotated access key 1 in over 90 days ({access_key_1_last_rotated.days} days). | O16: User {user['user']} does not have access keys. | P16: resource "aws_iam_access_key" "<example_resource_name>" { user = "<example_resource_name>" status = "Inactive" # Critical: disables the access key to ensure no active key is older than 90 days } | Q16: aws iam update-access-key --user-name <USER_NAME> --access-key-id <ACCESS_KEY_ID> --status Inactive | R16: https://docs.aws.amazon.com/IAM/latest/UserGuide/id_credentials_getting-report.html | S16: https://github.com/prowler-cloud/prowler/blob/master/prowler/providers/aws/services/iam/iam_rotate_access_key_90_days/iam_rotate_access_key_90_days.py | T16: =IF(OR(L16="critical",AND(L16="high",OR(K16="IAM",K16="network"))),"T3",IF(OR(L16="high",L16="medium"),"T2","T1")) -> T2
A17: P-016 | B17: 2.13 | C17: Ensure IAM users receive permissions only through groups | D17: 2 Identity and Access Management | E17: Level 1 | F17: Automated | G17: iam_policy_attached_only_to_group_or_roles | H17: IAM user has no inline or attached policies | I17: iam | J17: AwsIamUser | K17: IAM | L17: low | M17: Directly attached user policies hinder centralized control and cause privilege creep. If a user is compromised, excessive rights enable data exposure, resource tampering, and lateral movement, harming confidentiality and integrity. Revocation is error-prone, weakening separation of duties and auditability. | N17: User {user.name} has the policy {policy['PolicyName']} attached. | O17: User {user.name} has no inline or attached policies. | R17: https://docs.aws.amazon.com/securityhub/latest/userguide/iam-controls.html https://docs.aws.amazon.com/IAM/latest/UserGuide/best-practices.html | S17: https://github.com/prowler-cloud/prowler/blob/master/prowler/providers/aws/services/iam/iam_policy_attached_only_to_group_or_roles/iam_policy_attached_only_to_group_or_roles.py | T17: =IF(OR(L17="critical",AND(L17="high",OR(K17="IAM",K17="network"))),"T3",IF(OR(L17="high",L17="medium"),"T2","T1")) -> T1
A18: P-017 | B18: 2.14 | C18: Ensure IAM policies that allow full "*:*" administrative privileges are not attached | D18: 2 Identity and Access Management | E18: Level 1 | F18: Automated | G18: iam_aws_attached_policy_no_administrative_privileges | H18: Attached AWS-managed IAM policy does not allow ':' administrative privileges | I18: iam | J18: AwsIamPolicy | K18: IAM | L18: critical | M18: Unrestricted : access enables any action on any resource, risking: - Data exfiltration (confidentiality) - Unauthorized changes and policy tampering (integrity) - Service deletion or shutdown (availability) Attackers can disable logging, create backdoor principals, and expand lateral movement. | N18: {policy.type} policy {policy.name} is attached and allows '*:*' administrative privileges. | O18: {policy.type} policy {policy.name} is attached but does not allow '*:*' administrative privileges. | P18: # Replace full admin attachment with a non-admin policy (ensure AdministratorAccess is not attached) resource "aws_iam_role_policy_attachment" "<example_resource_name>" { role = "<example_resource_name>" policy_arn = "arn:aws:iam::aws:policy/ReadOnlyAccess" # FIX: avoids ':' admin privileges; replace AdministratorAccess } | R18: https://docs.aws.amazon.com/aws-managed-policy/latest/reference/AdministratorAccess.html http://docs.aws.amazon.com/IAM/latest/UserGuide/best-practices.html | S18: https://github.com/prowler-cloud/prowler/blob/master/prowler/providers/aws/services/iam/iam_aws_attached_policy_no_administrative_privileges/iam_aws_attached_policy_no_administrative_privileges.py | T18: =IF(OR(L18="critical",AND(L18="high",OR(K18="IAM",K18="network"))),"T3",IF(OR(L18="high",L18="medium"),"T2","T1")) -> T3
A19: P-018 | B19: 2.14 | C19: Ensure IAM policies that allow full "*:*" administrative privileges are not attached | D19: 2 Identity and Access Management | E19: Level 1 | F19: Automated | G19: iam_customer_attached_policy_no_administrative_privileges | H19: Attached IAM customer-managed policy does not allow ':' administrative privileges | I19: iam | J19: AwsIamPolicy | K19: IAM | L19: high | M19: Unrestricted admin access lets any attached principal perform any action on any resource, enabling data exfiltration, policy tampering, credential creation, logging disablement, and destructive deletions-compromising confidentiality, integrity, and availability across the account. | N19: {policy.type} policy {policy.name} is attached and allows '*:*' administrative privileges. | O19: {policy.type} policy {policy.name} is attached but does not allow '*:*' administrative privileges. | P19: # Terraform: Managed policy without ':' admin privileges resource "aws_iam_policy" "<example_resource_name>" { name = "<example_resource_name>" policy = jsonencode({ Version = "2012-10-17" Statement = [{ Effect = "Allow" Action = "iam:GetUser" # CRITICAL: not "" or ":"; removes admin privileges Resource = "" # CRITICAL: paired with specific action to avoid full admin }] }) } | Q19: aws iam create-policy-version --policy-arn <EXAMPLE_POLICY_ARN> --policy-document '{"Version":"2012-10-17","Statement":[{"Effect":"Allow","Action":"iam:GetUser","Resource":""}]}' --set-as-default | R19: http://docs.aws.amazon.com/IAM/latest/UserGuide/best-practices.html | S19: https://github.com/prowler-cloud/prowler/blob/master/prowler/providers/aws/services/iam/iam_customer_attached_policy_no_administrative_privileges/iam_customer_attached_policy_no_administrative_privileges.py | T19: =IF(OR(L19="critical",AND(L19="high",OR(K19="IAM",K19="network"))),"T3",IF(OR(L19="high",L19="medium"),"T2","T1")) -> T3
A20: P-019 | B20: 2.15 | C20: Ensure a support role has been created to manage incidents with AWS Support | D20: 2 Identity and Access Management | E20: Level 1 | F20: Automated | G20: iam_support_role_created | H20: At least one IAM role has the AWSSupportAccess managed policy attached | I20: iam | J20: AwsIamRole | K20: IAM | L20: low | M20: Without a dedicated support role: - Case creation and escalation can be delayed, prolonging outages (availability) - Teams may use admin/root, increasing blast radius (confidentiality/integrity) - Audit trails of support actions are weaker, hindering investigations | N20: AWS Support Access policy is not attached to any role. | O20: AWS Support Access policy attached to role {iam_client.entities_role_attached_to_support_policy[0]['RoleName']}. | P20: # IAM role with AWS Support access resource "aws_iam_role" "example_resource_name" { name = "example_resource_name" assume_role_policy = jsonencode({ Version = "2012-10-17", Statement = [{ Effect = "Allow", Principal = { AWS = "arn:aws:iam::<example_account_id>:user/<example_resource_name>" }, Action = "sts:AssumeRole" }] }) managed_policy_arns = [ "arn:aws:iam::aws:policy/AWSSupportAccess" # Critical: ensures this role has AWSSupportAccess (PASS) ] } | Q20: aws iam attach-role-policy --role-name <example_resource_name> --policy-arn arn:aws:iam::aws:policy/AWSSupportAccess | R20: https://docs.aws.amazon.com/awssupport/latest/user/using-service-linked-roles-sup.html https://docs.aws.amazon.com/aws-managed-policy/latest/reference/AWSSupportAccess.html | S20: https://github.com/prowler-cloud/prowler/blob/master/prowler/providers/aws/services/iam/iam_support_role_created/iam_support_role_created.py | T20: =IF(OR(L20="critical",AND(L20="high",OR(K20="IAM",K20="network"))),"T3",IF(OR(L20="high",L20="medium"),"T2","T1")) -> T1
A21: P-020 | B21: 2.16 | C21: Ensure IAM instance roles are used for AWS resource access from instances | D21: 2 Identity and Access Management | E21: Level 2 | F21: Automated | G21: ec2_instance_profile_attached | H21: EC2 instance is associated with an IAM instance profile role | I21: ec2 | J21: AwsEc2Instance | K21: compute | L21: medium | M21: Without an instance profile, apps often rely on long-term access keys on the host. Exposed keys can be used from anywhere to read data, alter resources, or disrupt services, impacting confidentiality, integrity, and availability. Keys may persist in AMIs, images, or logs, hindering rotation and amplifying blast radius. | N21: EC2 Instance {instance.id} not associated with an Instance Profile Role. | O21: EC2 Instance {instance.id} associated with Instance Profile Role {instance.instance_profile['Arn']}. | P21: # Attach an IAM instance profile to the EC2 instance resource "aws_instance" "example" { ami = "<AMI_ID>" instance_type = "<INSTANCE_TYPE>" iam_instance_profile = "<INSTANCE_PROFILE_NAME>" # Critical: associates an instance profile so the check passes } | Q21: aws ec2 associate-iam-instance-profile --instance-id <INSTANCE_ID> --iam-instance-profile Name=<INSTANCE_PROFILE_NAME> | R21: http://docs.aws.amazon.com/IAM/latest/UserGuide/id_roles_use_switch-role-ec2.html | S21: https://github.com/prowler-cloud/prowler/blob/master/prowler/providers/aws/services/ec2/ec2_instance_profile_attached/ec2_instance_profile_attached.py | T21: =IF(OR(L21="critical",AND(L21="high",OR(K21="IAM",K21="network"))),"T3",IF(OR(L21="high",L21="medium"),"T2","T1")) -> T2
A22: P-021 | B22: 2.17 | C22: Ensure that all expired SSL/TLS certificates stored in AWS IAM are removed | D22: 2 Identity and Access Management | E22: Level 1 | F22: Automated | G22: iam_no_expired_server_certificates_stored | H22: IAM server certificate is not expired | I22: iam | J22: AwsCertificateManagerCertificate | K22: IAM | L22: high | M22: Retaining expired TLS certificates risks availability loss from failed handshakes and browser warnings, eroding trust. If attached to endpoints, users may bypass warnings, weakening confidentiality and integrity. Stale certs also hinder secure rotation and may be picked by automation, causing outages. | N22: IAM Certificate {certificate.name} has expired {expiration_days} days ago. | O22: IAM Certificate {certificate.name} is not expired. | Q22: aws iam delete-server-certificate --server-certificate-name <CERTIFICATE_NAME> | R22: https://docs.aws.amazon.com/IAM/latest/UserGuide/id_credentials_server-certs.html | S22: https://github.com/prowler-cloud/prowler/blob/master/prowler/providers/aws/services/iam/iam_no_expired_server_certificates_stored/iam_no_expired_server_certificates_stored.py | T22: =IF(OR(L22="critical",AND(L22="high",OR(K22="IAM",K22="network"))),"T3",IF(OR(L22="high",L22="medium"),"T2","T1")) -> T3
A23: P-022 | B23: 2.18 | C23: Ensure that IAM External Access Analyzer is enabled for all regions | D23: 2 Identity and Access Management | E23: Level 1 | F23: Automated | G23: accessanalyzer_enabled | H23: IAM Access Analyzer is enabled | I23: accessanalyzer | J23: Other | K23: security | L23: low | M23: Without an active analyzer, visibility into unintended public, cross-account, or risky internal access is lost. Adversaries can exploit exposed S3, snapshots, KMS keys, or permissive role trusts for data exfiltration and escalation. Unused permissions persist, enlarging the attack surface. This degrades confidentiality and integrity. | N23: IAM Access Analyzer in account {accessanalyzer_client.audited_account} is not enabled. | O23: IAM Access Analyzer {analyzer.name} is enabled. | P23: resource "aws_accessanalyzer_analyzer" "example_resource" { analyzer_name = "example_resource" type = "ACCOUNT" # This line fixes the security issue } | Q23: aws accessanalyzer create-analyzer --analyzer-name example_resource --type ACCOUNT | R23: https://docs.aws.amazon.com/IAM/latest/UserGuide/access-analyzer-manage-external.html https://aws.amazon.com/iam/access-analyzer/ https://docs.aws.amazon.com/IAM/latest/UserGuide/access-analyzer-getting-started.html https://docs.aws.amazon.com/access-analyzer/latest/APIReference/API_CreateAnalyzer.html https://docs.aws.amazon.com/IAM/latest/UserGuide/what-is-access-analyzer.html https://docs.aws.amazon.com/IAM/latest/UserGuide/access-analyzer-create-external.html https://docs.aws.amazon.com/access-analyzer/latest/APIReference/Welcome.html https://docs.aws.amazon.com/IAM/latest/UserGuide/access-analyzer-create-internal.html | S23: https://github.com/prowler-cloud/prowler/blob/master/prowler/providers/aws/services/accessanalyzer/accessanalyzer_enabled/accessanalyzer_enabled.py | T23: =IF(OR(L23="critical",AND(L23="high",OR(K23="IAM",K23="network"))),"T3",IF(OR(L23="high",L23="medium"),"T2","T1")) -> T1
A24: P-023 | B24: 2.19 | C24: Ensure IAM users are managed centrally via identity federation or AWS Organizations for multi-account environments | D24: 2 Identity and Access Management | E24: Level 2 | F24: Manual | G24: iam_check_saml_providers_sts | H24: IAM SAML provider exists in the account | I24: iam | J24: Other | K24: IAM | L24: low | M24: Without SAML federation, users rely on long-lived IAM keys. Compromised keys enable persistent API access, causing data exfiltration (C), unauthorized resource or policy changes (I), and difficult revocation. Lack of IdP controls (e.g., MFA, session limits) weakens accountability and access governance. | N24: No SAML Providers found. | O24: SAML Provider {provider.name} has been found. | P24: # Create an IAM SAML provider to satisfy the check resource "aws_iam_saml_provider" "<example_resource_name>" { name = "<example_resource_name>" saml_metadata_document = file("<SAML_METADATA_XML_FILE>") # Critical: creates the SAML provider so the check passes } | Q24: aws iam create-saml-provider --name <SAML_PROVIDER_NAME> --saml-metadata-document file://<SAML_METADATA_XML_FILE> | R24: https://docs.aws.amazon.com/STS/latest/APIReference/API_AssumeRoleWithSAML.html | S24: https://github.com/prowler-cloud/prowler/blob/master/prowler/providers/aws/services/iam/iam_check_saml_providers_sts/iam_check_saml_providers_sts.py | T24: =IF(OR(L24="critical",AND(L24="high",OR(K24="IAM",K24="network"))),"T3",IF(OR(L24="high",L24="medium"),"T2","T1")) -> T1
A25: P-024 | B25: 2.20 | C25: Ensure access to AWSCloudShellFullAccess is restricted | D25: 2 Identity and Access Management | E25: Level 1 | F25: Manual | G25: iam_policy_cloudshell_admin_not_attached | H25: No IAM users, groups, or roles have the AWSCloudShellFullAccess policy attached | I25: iam | J25: AwsIamPolicy | K25: IAM | L25: medium | M25: Granting cloudshell: enables an interactive shell with Internet egress and file upload/download, degrading confidentiality and integrity. Compromised principals can exfiltrate data, stage tooling with sudo, persist artifacts in CloudShell, and operate from AWS IP space to bypass endpoint controls. | N25: AWS CloudShellFullAccess policy attached to IAM {', '.join(entity_strings)}. | O25: AWS CloudShellFullAccess policy is not attached to any IAM entity. | P25: # Terraform: ensure AWSCloudShellFullAccess is NOT attached resource "aws_iam_user_policy_attachment" "<example_resource_name>" { count = 0 # Critical: prevents creation, ensuring the policy is detached/not attached user = "<example_resource_name>" policy_arn = "arn:aws:iam::aws:policy/AWSCloudShellFullAccess" # Denied policy } | R25: https://docs.aws.amazon.com/securityhub/latest/userguide/iam-controls.html#iam-27 https://docs.aws.amazon.com/config/latest/developerguide/iam-policy-blacklisted-check.html https://docs.aws.amazon.com/IAM/latest/UserGuide/access_policies_manage-attach-detach.html | S25: https://github.com/prowler-cloud/prowler/blob/master/prowler/providers/aws/services/iam/iam_policy_cloudshell_admin_not_attached/iam_policy_cloudshell_admin_not_attached.py | T25: =IF(OR(L25="critical",AND(L25="high",OR(K25="IAM",K25="network"))),"T3",IF(OR(L25="high",L25="medium"),"T2","T1")) -> T2
A26: P-025 | B26: 2.21 | C26: Ensure AWS resource policies do not allow unrestricted access using 'Principal': '*' | D26: 2 Identity and Access Management | E26: Level 1 | F26: Manual | G26: s3_bucket_policy_public_write_access | H26: S3 bucket policy does not allow public write access | I26: s3 | J26: AwsS3Bucket | K26: storage | L26: critical | M26: Public write access lets anyone upload, overwrite, or delete objects, undermining integrity and availability. Attackers can plant malware, stage phishing content, poison data, or wipe buckets, causing outages and potential legal and cost impacts from storage abuse and content hosting. | N26: S3 Bucket {bucket.name} allows public write access in the bucket policy. | O26: S3 Bucket {bucket.name} does not have a bucket policy. | P26: # Enable bucket-level Public Access Block so public bucket policies (including write) are blocked resource "aws_s3_bucket_public_access_block" "<example_resource_name>" { bucket = "<example_resource_id>" restrict_public_buckets = true # Critical: prevents public access granted via bucket policies } | Q26: aws s3api put-public-access-block --bucket <BUCKET_NAME> --public-access-block-configuration RestrictPublicBuckets=true | R26: https://docs.aws.amazon.com/IAM/latest/UserGuide/reference_policies_examples_s3_rw-bucket.html | S26: https://github.com/prowler-cloud/prowler/blob/master/prowler/providers/aws/services/s3/s3_bucket_policy_public_write_access/s3_bucket_policy_public_write_access.py | T26: =IF(OR(L26="critical",AND(L26="high",OR(K26="IAM",K26="network"))),"T3",IF(OR(L26="high",L26="medium"),"T2","T1")) -> T3
A27: P-026 | B27: 2.21 | C27: Ensure AWS resource policies do not allow unrestricted access using 'Principal': '*' | D27: 2 Identity and Access Management | E27: Level 1 | F27: Manual | G27: sqs_queues_not_publicly_accessible | H27: SQS queue policy does not allow public access | I27: sqs | J27: AwsSqsQueue | K27: messaging | L27: critical | M27: Public SQS access can expose message data (confidentiality), enable unauthorized send/receive or tampering (integrity), and allow purge/delete operations that disrupt processing (availability). It may also trigger unbounded message ingestion, causing cost spikes and consumer overload. | N27: SQS queue {queue.id} is public because its policy allows public access, and the condition does not limit access to resources within the same account. | O27: SQS queue {queue.id} is not public. | P27: # Restrict SQS policy to a specific principal (not public) resource "aws_sqs_queue_policy" "<example_resource_name>" { queue_url = "<example_queue_url>" policy = jsonencode({ Version = "2012-10-17" Statement = [{ Effect = "Allow" Principal = { AWS = "<example_account_id>" } # CRITICAL: restrict to a specific principal (removes public "") Action = "sqs:" Resource = "<example_queue_arn>" }] }) } | Q27: aws sqs set-queue-attributes --queue-url <example_queue_url> --attributes Policy='{"Version":"2012-10-17","Statement":[{"Effect":"Allow","Principal":{"AWS":"<example_account_id>"},"Action":"sqs:","Resource":"<example_queue_arn>"}]}' | R27: https://docs.aws.amazon.com/AWSSimpleQueueService/latest/SQSDeveloperGuide/sqs-basic-examples-of-sqs-policies.html | S27: https://github.com/prowler-cloud/prowler/blob/master/prowler/providers/aws/services/sqs/sqs_queues_not_publicly_accessible/sqs_queues_not_publicly_accessible.py | T27: =IF(OR(L27="critical",AND(L27="high",OR(K27="IAM",K27="network"))),"T3",IF(OR(L27="high",L27="medium"),"T2","T1")) -> T3
A28: P-027 | B28: 2.21 | C28: Ensure AWS resource policies do not allow unrestricted access using 'Principal': '*' | D28: 2 Identity and Access Management | E28: Level 1 | F28: Manual | G28: sns_topics_not_publicly_accessible | H28: SNS topic is not publicly accessible | I28: sns | J28: AwsSnsTopic | K28: messaging | L28: high | M28: Public SNS topics allow anyone or unknown accounts to: - Subscribe and siphon messages (confidentiality) - Publish spoofed payloads that alter workflows (integrity) - Flood messages causing outages and costs (availability) They also enable cross-account abuse and bypass expected trust boundaries. | N28: SNS topic {topic.name} is public because its policy allows public access. | O28: SNS topic {topic.name} is not publicly accessible. | P28: # Restrict SNS topic policy to the account (not public) resource "aws_sns_topic_policy" "<example_resource_name>" { arn = "<TOPIC_ARN>" policy = jsonencode({ Version = "2012-10-17" Statement = [{ Effect = "Allow" Action = "sns:Publish" Resource = "<TOPIC_ARN>" Principal = { AWS = "arn:aws:iam::<ACCOUNT_ID>:root" } # Critical: restrict principal to the account to remove public access }] }) } | Q28: aws sns set-topic-attributes --topic-arn <TOPIC_ARN> --attribute-name Policy --attribute-value '{"Version":"2012-10-17","Statement":[{"Effect":"Allow","Principal":{"AWS":"arn:aws:iam::<ACCOUNT_ID>:root"},"Action":"sns:Publish","Resource":"<TOPIC_ARN>"}]}' | R28: https://docs.aws.amazon.com/config/latest/developerguide/sns-topic-policy.html | S28: https://github.com/prowler-cloud/prowler/blob/master/prowler/providers/aws/services/sns/sns_topics_not_publicly_accessible/sns_topics_not_publicly_accessible.py | T28: =IF(OR(L28="critical",AND(L28="high",OR(K28="IAM",K28="network"))),"T3",IF(OR(L28="high",L28="medium"),"T2","T1")) -> T2
A29: P-028 | B29: 2.21 | C29: Ensure AWS resource policies do not allow unrestricted access using 'Principal': '*' | D29: 2 Identity and Access Management | E29: Level 1 | F29: Manual | G29: awslambda_function_not_publicly_accessible | H29: Lambda function resource-based policy does not allow public access | I29: awslambda | J29: AwsLambdaFunction | K29: serverless | L29: critical | M29: Public invocation lets outsiders run code under the function's IAM role. Impacts: - Confidentiality: data exfiltration via backend access - Integrity: unauthorized state changes from side effects - Availability/cost: invocation floods causing throttling and spend spikes | N29: Lambda function {function.name} has a resource-based policy with public access. | O29: Lambda function {function.name} has a resource-based policy without public access. | P29: # Restrict Lambda permission to a non-public principal resource "aws_lambda_permission" "<example_resource_name>" { statement_id = "AllowSpecificPrincipal" action = "lambda:InvokeFunction" function_name = "<example_resource_name>" principal = "123456789012" # Critical: not ""; prevents public access } | Q29: aws lambda remove-permission --function-name <example_function_name> --statement-id <example_statement_id> | R29: https://docs.aws.amazon.com/config/latest/developerguide/lambda-function-public-access-prohibited.html https://docs.aws.amazon.com/lambda/latest/dg/access-control-resource-based.html https://docs.aws.amazon.com/securityhub/latest/userguide/lambda-controls.html | S29: https://github.com/prowler-cloud/prowler/blob/master/prowler/providers/aws/services/awslambda/awslambda_function_not_publicly_accessible/awslambda_function_not_publicly_accessible.py | T29: =IF(OR(L29="critical",AND(L29="high",OR(K29="IAM",K29="network"))),"T3",IF(OR(L29="high",L29="medium"),"T2","T1")) -> T3
A30: P-029 | B30: 2.21 | C30: Ensure AWS resource policies do not allow unrestricted access using 'Principal': '*' | D30: 2 Identity and Access Management | E30: Level 1 | F30: Manual | G30: kms_key_not_publicly_accessible | H30: Cloud KMS key does not grant access to allUsers or allAuthenticatedUsers | I30: kms | J30: AwsKmsKey | K30: security | L30: critical | M30: Broad access to a KMS key enables unauthorized kms:Decrypt and data-key generation, breaking confidentiality. With admin rights, attackers can change policies or schedule deletion, undermining control integrity and threatening availability of data dependent on the key. | N30: KMS key {key.id} may be publicly accessible. | O30: KMS key {key.id} is not exposed to Public. | P30: # Restrict KMS key policy to the account root to avoid any public ("") principals data "aws_caller_identity" "current" {} resource "aws_kms_key" "<example_resource_name>" { policy = jsonencode({ Version = "2012-10-17" Statement = [ { Effect = "Allow" Principal = { AWS = "arn:aws:iam::${data.aws_caller_identity.current.account_id}:root" } # Critical: limit to account root to remove public access Action = "kms:" Resource = "" } ] }) } | Q30: aws kms put-key-policy --key-id <example_resource_id> --policy-name default --policy '{"Version":"2012-10-17","Statement":[{"Effect":"Allow","Principal":{"AWS":"arn:aws:iam::<account_id>:root"},"Action":"kms:\","Resource":"\"}]}' | R30: https://docs.aws.amazon.com/kms/latest/developerguide/determining-access.html | S30: https://github.com/prowler-cloud/prowler/blob/master/prowler/providers/aws/services/kms/kms_key_not_publicly_accessible/kms_key_not_publicly_accessible.py | T30: =IF(OR(L30="critical",AND(L30="high",OR(K30="IAM",K30="network"))),"T3",IF(OR(L30="high",L30="medium"),"T2","T1")) -> T3
A31: P-030 | B31: 2.21 | C31: Ensure AWS resource policies do not allow unrestricted access using 'Principal': '*' | D31: 2 Identity and Access Management | E31: Level 1 | F31: Manual | G31: glacier_vaults_policy_public_access | H31: S3 Glacier vault has no policy or its policy does not allow access to everyone | I31: glacier | J31: Other | K31: storage | L31: critical | M31: Publicly grantable vault access undermines confidentiality and integrity. Anyone could list, retrieve, or delete archives, leading to data exposure or loss. Attackers may also trigger large retrieval operations, degrading availability and driving unexpected costs. | N31: Vault {vault.name} has policy which allows access to everyone. | O31: Vault {vault.name} has policy which does not allow access to everyone. | P31: # Glacier vault with no access policy (not public) resource "aws_glacier_vault" "<example_resource_name>" { name = "<example_resource_name>" # access_policy omitted to remove any public access and pass the check } | Q31: aws glacier delete-vault-access-policy --account-id <ACCOUNT_ID> --vault-name <VAULT_NAME> | R31: https://docs.aws.amazon.com/amazonglacier/latest/dev/access-control-overview.html | S31: https://github.com/prowler-cloud/prowler/blob/master/prowler/providers/aws/services/glacier/glacier_vaults_policy_public_access/glacier_vaults_policy_public_access.py | T31: =IF(OR(L31="critical",AND(L31="high",OR(K31="IAM",K31="network"))),"T3",IF(OR(L31="high",L31="medium"),"T2","T1")) -> T3
A32: P-031 | B32: 2.21 | C32: Ensure AWS resource policies do not allow unrestricted access using 'Principal': '*' | D32: 2 Identity and Access Management | E32: Level 1 | F32: Manual | G32: secretsmanager_not_publicly_accessible | H32: Secrets Manager secret resource policy does not allow public access | I32: secretsmanager | J32: AwsSecretsManagerSecret | K32: security | L32: high | M32: Public access to a secret enables uncontrolled retrieval of secret values, compromising confidentiality. If broad actions are allowed, attackers can modify or delete the secret, impacting integrity and availability, and use exposed credentials for unauthorized data access and lateral movement. | N32: SecretsManager secret {secret.name} is publicly accessible due to its resource policy. | O32: SecretsManager secret {secret.name} is not publicly accessible. | P32: # Restrict secret policy and block public access resource "aws_secretsmanager_secret_policy" "<example_resource_name>" { secret_arn = "<example_resource_id>" block_public_policy = true # Critical: blocks public policies policy = jsonencode({ # Critical: principal is not "" Version = "2012-10-17" Statement = [{ Effect = "Allow" Principal = { AWS = "arn:aws:iam::<ACCOUNT_ID>:root" } Action = "secretsmanager:GetSecretValue" Resource = "" }] }) } | Q32: aws secretsmanager put-resource-policy --secret-id <secret-id> --resource-policy '{"Version":"2012-10-17","Statement":[{"Effect":"Allow","Principal":{"AWS":"arn:aws:iam::<ACCOUNT_ID>:root"},"Action":"secretsmanager:GetSecretValue","Resource":""}]}' --block-public-policy | R32: https://docs.aws.amazon.com/secretsmanager/latest/userguide/auth-and-access_resource-policies.html https://docs.aws.amazon.com/secretsmanager/latest/userguide/determine-acccess_examine-iam-policies.html | S32: https://github.com/prowler-cloud/prowler/blob/master/prowler/providers/aws/services/secretsmanager/secretsmanager_not_publicly_accessible/secretsmanager_not_publicly_accessible.py | T32: =IF(OR(L32="critical",AND(L32="high",OR(K32="IAM",K32="network"))),"T3",IF(OR(L32="high",L32="medium"),"T2","T1")) -> T2
A33: P-032 | B33: 2.21 | C33: Ensure AWS resource policies do not allow unrestricted access using 'Principal': '*' | D33: 2 Identity and Access Management | E33: Level 1 | F33: Manual | G33: eventbridge_bus_exposed | H33: AWS EventBridge event bus policy does not allow public access | I33: eventbridge | J33: AwsEventsEventbus | K33: messaging | L33: high | M33: Publicly accessible event buses enable event injection and unauthorized rule changes, undermining integrity and enabling lateral movement. Attackers can trigger downstream targets, causing data exposure, service disruption, and unexpected costs through high-volume events. | N33: EventBridge event bus {bus.name} is exposed to everyone. | O33: EventBridge event bus {bus.name} is not exposed to everyone. | P33: resource "aws_cloudwatch_event_bus_policy" "<example_resource_name>" { # CRITICAL: Principal is a specific AWS account, not "", preventing public access policy = <<POLICY { "Version": "2012-10-17", "Statement": [{ "Sid": "AllowSpecificAccount", "Effect": "Allow", "Principal": {"AWS": "arn:aws:iam::<example_account_id>:root"}, "Action": "events:PutEvents", "Resource": "arn:aws:events:<example_region>:<example_account_id>:event-bus/default" }] } POLICY } | Q33: aws events remove-permission --event-bus-name <event_bus_name> --statement-id <statement_id> | R33: https://docs.aws.amazon.com/AmazonCloudWatch/latest/events/CloudWatchEvents-CrossAccountEventDelivery.html https://docs.aws.amazon.com/AmazonCloudWatch/latest/events/CWE_GettingStarted.html https://aws.amazon.com/blogs/compute/simplifying-cross-account-access-with-amazon-eventbridge-resource-policies/ | S33: https://github.com/prowler-cloud/prowler/blob/master/prowler/providers/aws/services/eventbridge/eventbridge_bus_exposed/eventbridge_bus_exposed.py | T33: =IF(OR(L33="critical",AND(L33="high",OR(K33="IAM",K33="network"))),"T3",IF(OR(L33="high",L33="medium"),"T2","T1")) -> T2
A34: P-033 | B34: 3.1.1 | C34: Ensure S3 Bucket Policy is set to deny HTTP requests | D34: 3 Storage | E34: Level 2 | F34: Automated | G34: s3_bucket_secure_transport_policy | H34: S3 bucket policy denies requests over insecure transport | I34: s3 | J34: AwsS3Bucket | K34: storage | L34: medium | M34: HTTP access exposes object data and auth details to eavesdropping and man-in-the-middle attacks. Captured pre-signed URLs can be replayed to exfiltrate data. Traffic can be intercepted or altered, undermining confidentiality and integrity of S3 content. | N34: S3 Bucket {bucket.name} does not have a bucket policy, thus it allows HTTP requests. | O34: S3 Bucket {bucket.name} has a bucket policy to deny requests over insecure transport. | P34: # Deny non-SSL (HTTP) requests to the S3 bucket resource "aws_s3_bucket_policy" "policy" { bucket = "<example_resource_name>" policy = jsonencode({ Version = "2012-10-17" Statement = [{ Effect = "Deny" Principal = "" Action = "s3:" Resource = "arn:aws:s3:::<example_resource_name>/" Condition = { Bool = { "aws:SecureTransport" = "false" # Critical: deny requests not using SSL/TLS } } }] }) } | Q34: aws s3api put-bucket-policy --bucket <example_resource_name> --policy '{"Version":"2012-10-17","Statement":[{"Effect":"Deny","Principal":"","Action":"s3:","Resource":"arn:aws:s3:::<example_resource_name>/","Condition":{"Bool":{"aws:SecureTransport":"false"}}}]}' | R34: https://aws.amazon.com/premiumsupport/knowledge-center/s3-bucket-policy-for-config-rule/ | S34: https://github.com/prowler-cloud/prowler/blob/master/prowler/providers/aws/services/s3/s3_bucket_secure_transport_policy/s3_bucket_secure_transport_policy.py | T34: =IF(OR(L34="critical",AND(L34="high",OR(K34="IAM",K34="network"))),"T3",IF(OR(L34="high",L34="medium"),"T2","T1")) -> T2
A35: P-034 | B35: 3.1.2 | C35: Ensure MFA Delete is enabled on S3 buckets | D35: 3 Storage | E35: Level 2 | F35: Manual | G35: s3_bucket_no_mfa_delete | H35: S3 bucket has MFA Delete enabled | I35: s3 | J35: AwsS3Bucket | K35: storage | L35: medium | M35: Without MFA Delete, a compromised or over-privileged identity can irrevocably purge object history or change versioning. This erases recovery points, degrading data availability, weakening integrity, and increasing the blast radius of account compromise or ransomware. | N35: S3 Bucket {bucket.name} has MFA Delete disabled. | O35: S3 Bucket {bucket.name} has MFA Delete enabled. | Q35: aws s3api put-bucket-versioning --bucket <BUCKET_NAME> --versioning-configuration Status=Enabled,MFADelete=Enabled --mfa "<MFA_SERIAL_OR_ARN> <MFA_CODE>" | R35: https://docs.aws.amazon.com/AmazonS3/latest/userguide/MultiFactorAuthenticationDelete.html https://docs.aws.amazon.com/AmazonS3/latest/userguide/UsingMFADelete.html | S35: https://github.com/prowler-cloud/prowler/blob/master/prowler/providers/aws/services/s3/s3_bucket_no_mfa_delete/s3_bucket_no_mfa_delete.py | T35: =IF(OR(L35="critical",AND(L35="high",OR(K35="IAM",K35="network"))),"T3",IF(OR(L35="high",L35="medium"),"T2","T1")) -> T2
A36: P-035 | B36: 3.1.3 | C36: Ensure all data in Amazon S3 has been discovered, classified, and secured when necessary | D36: 3 Storage | E36: Level 2 | F36: Manual | G36: macie_is_enabled | H36: Amazon Macie is enabled | I36: macie | J36: Other | K36: security | L36: medium | M36: Without active Macie, sensitive data in S3 can remain unclassified and exposed. Misconfigured access and public buckets may go undetected, enabling data exfiltration and secret leakage. This degrades confidentiality and widens breach blast radius by reducing visibility into where sensitive data resides. | N36: Macie is currently in a SUSPENDED state. | O36: Macie is enabled. | P36: # Enables Amazon Macie in this region resource "aws_macie2_account" "main" { # Critical: Creating this resource enables Macie for the account in the region } | Q36: aws macie2 enable-macie --region <REGION> | R36: https://aws.amazon.com/macie/getting-started/ | S36: https://github.com/prowler-cloud/prowler/blob/master/prowler/providers/aws/services/macie/macie_is_enabled/macie_is_enabled.py | T36: =IF(OR(L36="critical",AND(L36="high",OR(K36="IAM",K36="network"))),"T3",IF(OR(L36="high",L36="medium"),"T2","T1")) -> T2
A37: P-036 | B37: 3.1.4 | C37: Ensure that S3 is configured with 'Block Public Access' enabled | D37: 3 Storage | E37: Level 1 | F37: Automated | G37: s3_bucket_level_public_access_block | H37: S3 bucket has Block Public Access with IgnorePublicAcls and RestrictPublicBuckets enabled at bucket or account level | I37: s3 | J37: AwsS3Bucket | K37: storage | L37: high | M37: Absent S3 Block Public Access, public ACLs or broad policies can grant Internet or cross-account access. - Data disclosure (confidentiality) - Object overwrite or uploads (integrity) - Deletion or outages from misuse (availability) | N37: Block Public Access is not configured for the S3 Bucket {bucket.name}. | O37: Block Public Access is configured for the S3 Bucket {bucket.name}. | P37: # Enable required S3 Block Public Access settings on a bucket resource "aws_s3_bucket_public_access_block" "<example_resource_name>" { bucket = "<example_resource_id>" ignore_public_acls = true # CRITICAL: Ignore public ACLs restrict_public_buckets = true # CRITICAL: Restrict public buckets } | Q37: aws s3api put-public-access-block --bucket <BUCKET_NAME> --public-access-block-configuration IgnorePublicAcls=true,RestrictPublicBuckets=true | R37: https://docs.aws.amazon.com/AmazonS3/latest/userguide/access-control-block-public-access.html | S37: https://github.com/prowler-cloud/prowler/blob/master/prowler/providers/aws/services/s3/s3_bucket_level_public_access_block/s3_bucket_level_public_access_block.py | T37: =IF(OR(L37="critical",AND(L37="high",OR(K37="IAM",K37="network"))),"T3",IF(OR(L37="high",L37="medium"),"T2","T1")) -> T2
